2025-07-21 22:26:16,623:ERROR:{'message': 'division by zero', 'detail': 'Traceback (most recent call last):\n  File "/Users/fersoriano/Documents/programming/bootcamp-backend-python/python_exceptions/logs/context_manager.py", line 15, in write_on_log_error\n    yield\n  File "/Users/fersoriano/Documents/programming/bootcamp-backend-python/python_exceptions/logs/context_manager.py", line 27, in <module>\n    a = 10 / 0\n        ~~~^~~\nZeroDivisionError: division by zero\n'}
2025-07-21 22:26:16,623:ERROR:{'message': 'Se perdio la conexion a la Base de Datos', 'detail': 'Traceback (most recent call last):\n  File "/Users/fersoriano/Documents/programming/bootcamp-backend-python/python_exceptions/logs/context_manager.py", line 15, in write_on_log_error\n    yield\n  File "/Users/fersoriano/Documents/programming/bootcamp-backend-python/python_exceptions/logs/context_manager.py", line 31, in <module>\n    raise Exception("Se perdio la conexion a la Base de Datos")\nException: Se perdio la conexion a la Base de Datos\n'}
2025-07-21 22:36:11,659:ERROR:{'message': 'division by zero', 'detail': 'Traceback (most recent call last):\n  File "/Users/fersoriano/Documents/programming/cursos/Bootcamp_Python_Avanzado/python_exceptions/logs/context_manager.py", line 22, in write_on_log_error\n    yield  # actua como placeholder para reemplazar lo del bloque with\n    ^^^^^\n  File "/Users/fersoriano/Documents/programming/cursos/Bootcamp_Python_Avanzado/python_exceptions/logs/context_manager.py", line 34, in <module>\n    a = 10 / 0\n        ~~~^~~\nZeroDivisionError: division by zero\n'}
2025-07-21 22:36:11,659:ERROR:{'message': 'Se perdio la conexion a la Base de Datos', 'detail': 'Traceback (most recent call last):\n  File "/Users/fersoriano/Documents/programming/cursos/Bootcamp_Python_Avanzado/python_exceptions/logs/context_manager.py", line 22, in write_on_log_error\n    yield  # actua como placeholder para reemplazar lo del bloque with\n    ^^^^^\n  File "/Users/fersoriano/Documents/programming/cursos/Bootcamp_Python_Avanzado/python_exceptions/logs/context_manager.py", line 38, in <module>\n    raise Exception("Se perdio la conexion a la Base de Datos")\nException: Se perdio la conexion a la Base de Datos\n'}
2025-07-21 22:36:11,659:ERROR:{'message': "[Errno 2] No such file or directory: 'test.txt'", 'detail': 'Traceback (most recent call last):\n  File "/Users/fersoriano/Documents/programming/cursos/Bootcamp_Python_Avanzado/python_exceptions/logs/context_manager.py", line 22, in write_on_log_error\n    yield  # actua como placeholder para reemplazar lo del bloque with\n    ^^^^^\n  File "/Users/fersoriano/Documents/programming/cursos/Bootcamp_Python_Avanzado/python_exceptions/logs/context_manager.py", line 41, in <module>\n    file = open(\'test.txt\')\n           ^^^^^^^^^^^^^^^^\nFileNotFoundError: [Errno 2] No such file or directory: \'test.txt\'\n'}
